<?xml version="1.0" encoding="utf-8"?>
<!-- =================================================================================== -->
<!-- |    This document was autogenerated by xacro from /home/johannes/catkin_ws/src/mabi_mobile/mabi_mobile_description/urdf/mabi_mobile.urdf.xacro | -->
<!-- |    EDITING THIS FILE BY HAND IS NOT RECOMMENDED                                 | -->
<!-- =================================================================================== -->
<robot name="mabi_mobile">
  <material name="black">
    <color rgba="0.0 0.0 0.0 1.0"/>
  </material>
  <material name="blue">
    <color rgba="0.0 0.0 0.8 1.0"/>
  </material>
  <material name="green">
    <color rgba="0.0 0.8 0.0 1.0"/>
  </material>
  <material name="grey">
    <color rgba="0.2 0.2 0.2 1.0"/>
  </material>
  <material name="light_grey">
    <color rgba="0.4 0.4 0.4 1.0"/>
  </material>
  <material name="orange">
    <color rgba="1.0 0.423529411765 0.0392156862745 1.0"/>
  </material>
  <material name="brown">
    <color rgba="0.870588235294 0.811764705882 0.764705882353 1.0"/>
  </material>
  <material name="red">
    <color rgba="0.8 0.0 0.0 1.0"/>
  </material>
  <material name="white">
    <color rgba="1.0 1.0 1.0 1.0"/>
  </material>
  <!-- [m] -->
  <!-- [m] -->
  <!-- [m] -->
  <!-- [m] -->
  <!-- [m] -->
  <!-- [m] -->
  <!-- [m] -->
  <!-- [m] -->
  <!-- [m] -->
  <!-- ====== -->
  <!-- [Nm] friction -->
  <!-- [Nm] -->
  <!-- [Nm] -->
  <!-- [Nm] -->
  <!-- [Nm] -->
  <!-- [Nm] -->
  <material name="mabi_red">
    <color rgba="0.698039215686 0.133333333333 0.133333333333 1.0"/>
  </material>
  <link name="BASE_ADAPTER_1">
    <visual>
      <origin rpy="0 0 0" xyz="0 0 0.009"/>
      <geometry>
        <cylinder length="0.018" radius="0.1"/>
      </geometry>
      <material name="gray">
        <color rgba="0.411764705882 0.411764705882 0.411764705882 1.0"/>
      </material>
    </visual>
    <collision name="collision">
      <origin rpy="0 0 0" xyz="0 0 0.009"/>
      <geometry>
        <cylinder length="0.018" radius="0.1"/>
      </geometry>
    </collision>
    <inertial>
      <origin rpy="0 0 0" xyz="0 0 0"/>
      <mass value="1.28"/>
      <inertia ixx="0.00063" ixy="0.0" ixz="0.0" iyy="0.00063" iyz="0.0" izz="0.0125"/>
    </inertial>
  </link>
  <!-- Joint: BASE_ADAPTER_1_JOINT -->
  <joint name="BASE_ADAPTER_1_JOINT" type="fixed">
    <parent link="arm_base"/>
    <child link="BASE_ADAPTER_1"/>
    <origin rpy="0 0 0" xyz="0.0 0.0 0.0"/>
  </joint>
  <!-- Gazebo customization -->
  <gazebo reference="BASE_ADAPTER_1">
    <kp>1000000.0</kp>
    <kd>1.5</kd>
    <mu1>1.2</mu1>
    <mu2>1.2</mu2>
    <self_collide>1</self_collide>
  </gazebo>
  <!-- -0.055/2-0.018, -sensor/2-adapter2  [m] -->
  <!-- Joint: SENSOR_FRAME -->
  <joint name="BASE_FORCETORQUESENSOR_FRAME" type="fixed">
    <parent link="BASE_ADAPTER_1"/>
    <child link="BASE_FORCETORQUESENSOR"/>
    <origin rpy="0.0 0.0 0.0" xyz="0.0 0.0 0.091"/>
    <limit effort="0" lower="0" upper="0" velocity="0"/>
  </joint>
  <!-- sensor link -->
  <link name="BASE_FORCETORQUESENSOR">
    <visual>
      <origin rpy="3.141593 0.0 0.0" xyz="0.0 0.0 -0.028"/>
      <geometry>
        <mesh filename="package://perceptive_mpc/urdf/mabi/meshes/RKL100.stl" scale="0.001 0.001 0.001"/>
      </geometry>
      <material name="gray">
        <color rgba="0.411764705882 0.411764705882 0.411764705882 1.0"/>
      </material>
    </visual>
    <inertial>
      <origin rpy="0 0 1.57079327" xyz="0.0 0.0 -0.033"/>
      <mass value="2.5"/>
      <inertia ixx="0.0" ixy="0.0" ixz="0.0" iyy="0.0" iyz="0.0" izz="0.0"/>
    </inertial>
    <collision name="collision">
      <origin rpy="0 0 0" xyz="0.0 0.0 -0.0455"/>
      <geometry>
        <cylinder length="0.055" radius="0.1"/>
      </geometry>
    </collision>
  </link>
  <joint name="BASE_FORCETORQUESENSOR_JOINT" type="fixed">
    <parent link="BASE_FORCETORQUESENSOR"/>
    <child link="arm_mount"/>
    <origin rpy="0 0 0" xyz="0 0 0"/>
    <limit effort="0" lower="0" upper="0" velocity="0"/>
  </joint>
  <!-- Gazebo customization -->
  <gazebo reference="BASE_FORCETORQUESENSOR">
    <kp>1000000.0</kp>
    <kd>1.5</kd>
    <mu1>1000000000</mu1>
    <mu2>1000000000</mu2>
    <self_collide>1</self_collide>
  </gazebo>
  <gazebo reference="BASE_FORCETORQUESENSOR_JOINT">
    <provideFeedback>1</provideFeedback>
  </gazebo>
  <link name="BASE_IMU"/>
  <joint name="BASE_IMU_JOINT" type="fixed">
    <origin rpy="0 0 0" xyz="0 0 0"/>
    <parent link="BASE_FORCETORQUESENSOR"/>
    <child link="BASE_IMU"/>
  </joint>
  <link name="arm_mount">
    <visual>
      <origin rpy="0 0 0" xyz="0.0 0.0 -0.009"/>
      <geometry>
        <cylinder length="0.018" radius="0.1"/>
      </geometry>
      <material name="gray">
        <color rgba="0.411764705882 0.411764705882 0.411764705882 1.0"/>
      </material>
    </visual>
    <collision name="collision">
      <origin rpy="0 0 0" xyz="0 0 0.009"/>
      <geometry>
        <cylinder length="0.017" radius="0.1"/>
        <!-- -0.001 to prevent collision with base sensor if revolute sensor joint bends-->
      </geometry>
    </collision>
    <inertial>
      <origin rpy="0 0 0" xyz="0 0 0"/>
      <mass value="1.28"/>
      <inertia ixx="0.5" ixy="0.0" ixz="0.0" iyy="0.5" iyz="0.0" izz="0.0"/>
    </inertial>
  </link>
  <!-- Gazebo customization -->
  <gazebo reference="arm_mount">
    <kp>1000000.0</kp>
    <kd>1.5</kd>
    <mu1>1.2</mu1>
    <mu2>1.2</mu2>
    <self_collide>1</self_collide>
  </gazebo>
  <!-- shoulder link -->
  <link name="SHOULDER">
    <visual>
      <origin rpy="0 0 0" xyz="0 0 0"/>
      <geometry>
        <mesh filename="package://perceptive_mpc/urdf/mabi/meshes/shoulder.STL" scale="0.001 0.001 0.001"/>
      </geometry>
      <material name="mabi_red"/>
    </visual>
    <collision name="collision">
      <origin rpy="0.0 0.0 0.0" xyz="0.0 0.0 -0.03"/>
      <geometry>
        <cylinder length="0.31" radius="0.09"/>
      </geometry>
    </collision>
    <inertial>
      <origin rpy="0 0 0" xyz="-0.047924822 0.0 -0.002274739"/>
      <mass value="7.6494994"/>
      <inertia ixx="0.029999999" ixy="3.2869e-05" ixz="0.000721956" iyy="0.059745945" iyz="1.0358e-05" izz="0.056496362"/>
    </inertial>
  </link>
  <!-- Joint: SH_ROT -->
  <joint name="SH_ROT" type="revolute">
    <parent link="arm_mount"/>
    <child link="SHOULDER"/>
    <origin rpy="0 0 0" xyz="0.0 0.0 0.189"/>
    <axis xyz="0 0 1"/>
    <limit effort="150.0" lower="-5.23598775598" upper="5.23598775598" velocity="1.308996939"/>
    <dynamics damping="0.1" friction="0.3"/>
  </joint>
  <!-- Gazebo customization -->
  <gazebo reference="SHOULDER">
    <kp>1000000.0</kp>
    <kd>1.5</kd>
    <mu1>1.2</mu1>
    <mu2>1.2</mu2>
    <self_collide>1</self_collide>
  </gazebo>
  <gazebo reference="SH_ROT">
        </gazebo>
  <!-- arm link -->
  <link name="ARM">
    <visual>
      <origin rpy="0 0 0" xyz="0 0 0"/>
      <geometry>
        <mesh filename="package://perceptive_mpc/urdf/mabi/meshes/arm.STL" scale="0.001 0.001 0.001"/>
      </geometry>
      <material name="mabi_red"/>
    </visual>
    <collision name="collision_motor_1">
      <origin rpy="0.0 0.0 0.0" xyz="0.0 0.0 0.205"/>
      <geometry>
        <cylinder length="0.22" radius="0.09"/>
      </geometry>
    </collision>
    <collision name="collision_arm">
      <origin rpy="0.0 1.57079632679 0.0" xyz="0.36 0.0 0.195"/>
      <geometry>
        <cylinder length="0.52" radius="0.085"/>
      </geometry>
    </collision>
    <collision name="collision_motor_2">
      <origin rpy="0.0 0.0 0.0" xyz="0.7 0.0 0.205"/>
      <geometry>
        <cylinder length="0.19" radius="0.07"/>
      </geometry>
    </collision>
    <inertial>
      <origin rpy="0 0 0" xyz="0.29409722 0.0 0.19270522"/>
      <mass value="13.640494"/>
      <inertia ixx="0.060898243" ixy="-0.00013513623" ixz="-0.013074267" iyy="1.1757653" iyz="-2.6102602e-05" izz="1.1722998"/>
    </inertial>
  </link>
  <!-- Joint: SH_FLE -->
  <joint name="SH_FLE" type="revolute">
    <parent link="SHOULDER"/>
    <child link="ARM"/>
    <origin rpy="-1.57079632679 0 1.57079632679" xyz="0.0 0.0 0.0"/>
    <axis xyz="0 0 1"/>
    <limit effort="150.0" lower="-3.14159265359" upper="0.0" velocity="1.308996939"/>
    <dynamics damping="0.1" friction="0.3"/>
  </joint>
  <!-- Gazebo customization -->
  <gazebo reference="ARM">
    <kp>1000000.0</kp>
    <kd>1.5</kd>
    <mu1>1.2</mu1>
    <mu2>1.2</mu2>
  </gazebo>
  <gazebo reference="SH_FLE">
        </gazebo>
  <!-- Elbow link -->
  <link name="ELBOW">
    <visual>
      <origin rpy="0 0 0" xyz="0 0 0.0"/>
      <geometry>
        <mesh filename="package://perceptive_mpc/urdf/mabi/meshes/elbow.STL" scale="0.001 0.001 0.001"/>
      </geometry>
      <material name="mabi_red"/>
    </visual>
    <collision name="collision">
      <origin rpy="0.0 1.57079632679 0.0" xyz="0.115 0.0 0.0"/>
      <geometry>
        <cylinder length="0.46" radius="0.066"/>
      </geometry>
    </collision>
    <inertial>
      <origin rpy="0 0 0" xyz="-0.0045213596 -0.0001046407 0.035705904"/>
      <mass value="4.6480036"/>
      <inertia ixx="0.021549076" ixy="-2.5845846e-05" ixz="-0.00062888563" iyy="0.02331519" iyz="-3.1906253e-05" izz="0.011591539"/>
    </inertial>
  </link>
  <!-- Joint: EL_FLE -->
  <joint name="EL_FLE" type="revolute">
    <parent link="ARM"/>
    <child link="ELBOW"/>
    <origin rpy="0 0 0" xyz="0.7 0.0 0.04"/>
    <axis xyz="0 0 1"/>
    <limit effort="100.0" lower="-2.47836753783" upper="2.47836753783" velocity="2.53072741539"/>
    <dynamics damping="0.1" friction="0.2"/>
  </joint>
  <!-- Gazebo customization -->
  <gazebo reference="ELBOW">
    <kp>1000000.0</kp>
    <kd>1.5</kd>
    <mu1>1.2</mu1>
    <mu2>1.2</mu2>
  </gazebo>
  <gazebo reference="EL_FLE">
        </gazebo>
  <!-- Forearm link -->
  <link name="FOREARM">
    <visual>
      <origin rpy="0 0 0" xyz="0 0 0"/>
      <geometry>
        <mesh filename="package://perceptive_mpc/urdf/mabi/meshes/forearm.STL" scale="0.001 0.001 0.001"/>
      </geometry>
      <material name="mabi_red"/>
    </visual>
    <collision name="collision_farm">
      <origin rpy="0.0 0.0 0.0" xyz="0.0 0.115 0.37"/>
      <geometry>
        <cylinder length="0.25" radius="0.048"/>
      </geometry>
    </collision>
    <collision name="collision_motor">
      <origin rpy="1.57079632679 0.0 0.0" xyz="0.0 0.13 0.55"/>
      <geometry>
        <cylinder length="0.145" radius="0.05"/>
      </geometry>
    </collision>
    <inertial>
      <origin rpy="0 0 0" xyz="-0.00051024005 0.047442921 0.27441632"/>
      <mass value="5.7271652"/>
      <inertia ixx="0.24731453" ixy="-0.00015557711" ixz="-0.0003643398" iyy="0.2306736" iyz="-0.05673063" izz="0.029585235"/>
    </inertial>
  </link>
  <!-- Joint: EL_ROT -->
  <joint name="EL_ROT" type="revolute">
    <parent link="ELBOW"/>
    <child link="FOREARM"/>
    <origin rpy="1.57079632679 0 1.57079632679" xyz="0.0 0.0 0.0"/>
    <axis xyz="0 0 1"/>
    <limit effort="40.0" lower="-5.23598775598" upper="5.23598775598" velocity="2.53072741539"/>
    <dynamics damping="0.1" friction="0.2"/>
  </joint>
  <!-- Gazebo customization -->
  <gazebo reference="FOREARM">
    <kp>1000000.0</kp>
    <kd>1.5</kd>
    <mu1>1.2</mu1>
    <mu2>1.2</mu2>
  </gazebo>
  <gazebo reference="EL_ROT">
        </gazebo>
  <!-- wrist1 link -->
  <link name="WRIST_1">
    <visual>
      <origin rpy="0 0 0" xyz="0 0 0.0"/>
      <geometry>
        <mesh filename="package://perceptive_mpc/urdf/mabi/meshes/wrist.STL" scale="0.001 0.001 0.001"/>
      </geometry>
      <material name="mabi_red"/>
    </visual>
    <collision name="collision">
      <origin rpy="1.57079632679 0.0 0.0" xyz="0.0 0.016 0.0"/>
      <geometry>
        <cylinder length="0.148" radius="0.05"/>
      </geometry>
    </collision>
    <inertial>
      <origin rpy="0 0 0" xyz="0.0 0.0 0.0"/>
      <mass value="1.9710281"/>
      <inertia ixx="0.0066945672" ixy="4.5275e-06" ixz="-7.5009e-06" iyy="0.0055642118" iyz="0.0003509941" izz="0.0038716147"/>
    </inertial>
  </link>
  <!-- Joint: WR_FLE -->
  <joint name="WR_FLE" type="revolute">
    <parent link="FOREARM"/>
    <child link="WRIST_1"/>
    <origin rpy="-1.57079632679 0 0" xyz="0.0 0.0 0.55"/>
    <axis xyz="0 0 1"/>
    <limit effort="40.0" lower="-2.39110107523" upper="2.39110107523" velocity="4.79965544298"/>
    <dynamics damping="0.1" friction="0.1"/>
  </joint>
  <!-- Gazebo customization -->
  <gazebo reference="WRIST_1">
    <kp>1000000.0</kp>
    <kd>1.5</kd>
    <mu1>1.2</mu1>
    <mu2>1.2</mu2>
  </gazebo>
  <gazebo reference="WR_FLE">
        </gazebo>
  <!-- Wrist2 link -->
  <link name="WRIST_2">
    <visual>
      <origin rpy="0 0 0" xyz="0 0.0 -0.01"/>
      <geometry>
        <mesh filename="package://perceptive_mpc/urdf/mabi/meshes/tool.STL" scale="0.001 0.001 0.001"/>
      </geometry>
      <material name="silver">
        <color rgba="0.737254901961 0.776470588235 0.8 1.0"/>
      </material>
    </visual>
    <collision name="collision">
      <origin rpy="0.0 0.0 0.0" xyz="0.0 0.0 -0.02"/>
      <geometry>
        <cylinder length="0.038" radius="0.05"/>
      </geometry>
    </collision>
    <inertial>
      <origin rpy="0 0 0" xyz="-0.00038203947 -0.0019245031 -0.03"/>
      <mass value="1.7057686"/>
      <inertia ixx="0.0046630423" ixy="-1.6647842e-07" ixz="-2.5100296e-05" iyy="0.0046335717" iyz="4.8450275e-05" izz="0.002284043"/>
    </inertial>
  </link>
  <!-- Joint: WR_ROT -->
  <joint name="WR_ROT" type="revolute">
    <parent link="WRIST_1"/>
    <child link="WRIST_2"/>
    <origin rpy="1.57079632679 0 0" xyz="0.0 -0.1 0.0"/>
    <axis xyz="0 0 1"/>
    <limit effort="40.0" lower="-3.14159265359" upper="3.14159265359" velocity="4.79965544298"/>
    <dynamics damping="0.1" friction="0.1"/>
  </joint>
  <!-- Gazebo customization -->
  <gazebo reference="WRIST_2">
    <kp>1000000.0</kp>
    <kd>1.5</kd>
    <mu1>1.2</mu1>
    <mu2>1.2</mu2>
  </gazebo>
  <gazebo reference="WR_ROT">
        </gazebo>
  <!-- [m] -->
  <!-- Joint: SENSOR_FRAME -->
  <joint name="EE_FORCETORQUESENSOR_FRAME" type="fixed">
    <parent link="WRIST_2"/>
    <child link="EE_FORCETORQUESENSOR"/>
    <origin rpy="0.0 0.0 0" xyz="0.0 0.0 0.034"/>
    <limit effort="0" lower="0" upper="0" velocity="0"/>
  </joint>
  <!-- sensor link -->
  <link name="EE_FORCETORQUESENSOR">
    <visual>
      <origin rpy="1.570796327 0.0 1.57079327" xyz="-0.2458 -0.1323 -0.034"/>
      <geometry>
        <mesh filename="package://perceptive_mpc/urdf/mabi/meshes/R212.STL" scale="0.001 0.001 0.001"/>
      </geometry>
      <material name="gray">
        <color rgba="0.411764705882 0.411764705882 0.411764705882 1.0"/>
      </material>
    </visual>
    <inertial>
      <origin rpy="0 0 1.57079327" xyz="0.0 0.0 -0.017"/>
      <mass value="0.23"/>
      <inertia ixx="0.0" ixy="0.0" ixz="0.0" iyy="0.0" iyz="0.0" izz="0.0"/>
    </inertial>
    <collision name="collision">
      <origin rpy="0 0 0" xyz="0.0 0.0 -0.017"/>
      <geometry>
        <cylinder length="0.034" radius="0.034"/>
      </geometry>
    </collision>
  </link>
  <joint name="EE_FORCETORQUESENSOR_JOINT" type="fixed">
    <parent link="EE_FORCETORQUESENSOR"/>
    <child link="FT_FLANGE"/>
    <origin rpy="0 0 0" xyz="0 0 0"/>
    <limit effort="0" lower="0" upper="0" velocity="0"/>
  </joint>
  <!-- Gazebo customization -->
  <gazebo reference="EE_FORCETORQUESENSOR">
    <kp>1000000.0</kp>
    <kd>1.5</kd>
    <mu1>1000000000</mu1>
    <mu2>1000000000</mu2>
    <self_collide>1</self_collide>
  </gazebo>
  <gazebo reference="EE_FORCETORQUESENSOR_JOINT">
    <provideFeedback>1</provideFeedback>
  </gazebo>
  <link name="EE_IMU"/>
  <joint name="EE_IMU_JOINT" type="fixed">
    <origin rpy="0 0 0" xyz="0 0 0"/>
    <parent link="EE_FORCETORQUESENSOR"/>
    <child link="EE_IMU"/>
  </joint>
  <link name="FT_FLANGE"/>
  <joint name="robotiq_coupler_coupler_joint" type="fixed">
    <!-- total height of coupler, minus the depth of robot end-effector shape and the gripper small depth-->
    <origin rpy="0 0 1.57079632679" xyz="0 0 0.0079"/>
    <parent link="FT_FLANGE"/>
    <child link="robotiq_coupler"/>
  </joint>
  <link name="robotiq_coupler">
    <visual>
      <origin rpy="0 0 0" xyz="0 0 -0.00395"/>
      <geometry>
        <!-- only the visible part of the coupler -->
        <cylinder length="0.0139" radius="0.0375"/>
      </geometry>
      <material name="dark_grey">
        <color rgba="0.05 0.05 0.05 1"/>
      </material>
    </visual>
    <collision>
      <origin rpy="0 0 0" xyz="0 0 0"/>
      <geometry>
        <cylinder length="0.0139" radius="0.0375"/>
      </geometry>
    </collision>
    <inertial>
      <mass value="0.1"/>
      <origin xyz="0 0 0.00695"/>
      <inertia ixx="3.67663333333e-05" ixy="0" ixz="0" iyy="3.67663333333e-05" iyz="0" izz="7.03125e-05"/>
    </inertial>
  </link>
  <!-- base -->
  <joint name="robotiq_coupler_GRIPPER_BASE_joint" type="fixed">
    <limit effort="0" lower="0" upper="0" velocity="0"/>
    <parent link="robotiq_coupler"/>
    <child link="GRIPPER_BASE"/>
  </joint>
  <link name="GRIPPER_BASE">
    <inertial>
      <mass value="0.2"/>
      <origin xyz="0 0 0.0075"/>
      <inertia ixx="0.00011375" ixy="0" ixz="0" iyy="0.00011375" iyz="0" izz="0.00016"/>
    </inertial>
    <visual>
      <geometry>
        <mesh filename="package://perceptive_mpc/urdf/mabi/meshes/base.stl" scale="0.001 0.001 0.001"/>
      </geometry>
    </visual>
    <collision>
      <origin rpy="0 0 0" xyz="0 0 0.015"/>
      <geometry>
        <cylinder length="0.045" radius="0.04"/>
      </geometry>
    </collision>
    <collision>
      <origin rpy="0 0 0" xyz="0 0 0.06"/>
      <geometry>
        <box size="0.03 0.04 0.06"/>
      </geometry>
    </collision>
  </link>
  <gazebo reference="GRIPPER_BASE">
    <kp>1000000.0</kp>
    <kd>1.5</kd>
    <mu1>1.2</mu1>
    <mu2>1.2</mu2>
  </gazebo>
  <!-- right finger -->
  <joint name="GRIPPER_JOINT" type="fixed">
    <origin rpy="0 0 0" xyz="0 0.0306011 0.054904"/>
    <parent link="GRIPPER_BASE"/>
    <child link="GRIPPER_right_driver"/>
    <axis xyz="1 0 0"/>
    <limit effort="60" lower="0.0" upper="0.872664444444" velocity="1.91986177778"/>
  </joint>
  <link name="GRIPPER_right_driver">
    <inertial>
      <mass value="0.05"/>
      <origin rpy="0 0 0" xyz="0 0.02 0"/>
      <inertia ixx="8.33333333333e-06" ixy="0" ixz="0" iyy="3.33333333333e-06" iyz="0" izz="8.33333333333e-06"/>
    </inertial>
    <visual>
      <geometry>
        <mesh filename="package://perceptive_mpc/urdf/mabi/meshes/driver.dae" scale="0.001 0.001 0.001"/>
      </geometry>
    </visual>
    <collision>
      <origin rpy="-0.1 0 0" xyz="0 0.02 0"/>
      <geometry>
        <box size="0.02 0.04 0.02"/>
      </geometry>
    </collision>
  </link>
  <joint name="GRIPPER_right_coupler_joint" type="fixed">
    <origin rpy="0 0 0" xyz="0 0.0315 -0.0041"/>
    <parent link="GRIPPER_right_driver"/>
    <child link="GRIPPER_right_coupler"/>
  </joint>
  <link name="GRIPPER_right_coupler">
    <inertial>
      <mass value="0.05"/>
      <origin rpy="-1.7 0 0" xyz="0 0.0 0.025"/>
      <inertia ixx="1.92708333333e-05" ixy="0" ixz="0" iyy="5.41666666667e-06" iyz="0" izz="2.13541666667e-05"/>
    </inertial>
    <visual>
      <geometry>
        <mesh filename="package://perceptive_mpc/urdf/mabi/meshes/coupler.dae" scale="0.001 0.001 0.001"/>
      </geometry>
    </visual>
    <collision>
      <origin rpy="-1.7 0 0" xyz="0 0.0 0.025"/>
      <geometry>
        <box size="0.03 0.065 0.02"/>
      </geometry>
    </collision>
  </link>
  <joint name="GRIPPER_right_follower_joint" type="fixed">
    <origin rpy="0 0 0" xyz="0 0.0061 0.0471"/>
    <parent link="GRIPPER_right_coupler"/>
    <child link="GRIPPER_right_follower"/>
    <axis xyz="1 0 0"/>
    <limit effort="176" lower="-2.96705911111" upper="2.96705911111" velocity="1.91986177778"/>
    <mimic joint="GRIPPER_JOINT" multiplier="-1"/>
  </joint>
  <link name="GRIPPER_right_follower">
    <inertial>
      <mass value="0.05"/>
      <origin xyz="0 -0.018 0.022"/>
      <inertia ixx="1.05375e-05" ixy="0" ixz="0" iyy="1.12666666667e-05" iyz="0" izz="2.60416666667e-06"/>
    </inertial>
    <visual>
      <geometry>
        <mesh filename="package://perceptive_mpc/urdf/mabi/meshes/follower.dae" scale="0.001 0.001 0.001"/>
      </geometry>
    </visual>
    <collision>
      <origin rpy="0 0 0" xyz="0 -0.018 0.022"/>
      <geometry>
        <box size="0.02 0.015 0.048"/>
      </geometry>
    </collision>
  </link>
  <joint name="GRIPPER_right_pad_joint" type="fixed">
    <parent link="GRIPPER_right_follower"/>
    <child link="GRIPPER_right_pad"/>
  </joint>
  <link name="GRIPPER_right_pad">
    <inertial>
      <mass value="0.01"/>
      <origin xyz="0 -0.022 0.031"/>
      <inertia ixx="1.13333333333e-06" ixy="0" ixz="0" iyy="1.41333333333e-06" iyz="0" izz="3.86666666667e-07"/>
    </inertial>
    <visual>
      <geometry>
        <mesh filename="package://perceptive_mpc/urdf/mabi/meshes/pad.dae" scale="0.001 0.001 0.001"/>
      </geometry>
    </visual>
    <collision>
      <origin rpy="0 0 0" xyz="0 -0.022 0.031"/>
      <geometry>
        <box size="0.02 0.008 0.036"/>
      </geometry>
    </collision>
  </link>
  <gazebo reference="GRIPPER_right_pad">
    <kp>1000000.0</kp>
    <kd>1.5</kd>
    <mu1>1.2</mu1>
    <mu2>1.2</mu2>
  </gazebo>
  <joint name="GRIPPER_right_spring_link_joint" type="fixed">
    <origin rpy="0 0 0" xyz="0 0.012 0.0614"/>
    <parent link="GRIPPER_BASE"/>
    <child link="GRIPPER_right_spring_link"/>
    <axis xyz="1 0 0"/>
    <limit effort="176" lower="-2.96705911111" upper="2.96705911111" velocity="1.91986177778"/>
    <mimic joint="GRIPPER_JOINT" multiplier="1"/>
  </joint>
  <link name="GRIPPER_right_spring_link">
    <inertial>
      <mass value="0.05"/>
      <origin rpy="-0.7068 0 0" xyz="0 0.018 0.018"/>
      <inertia ixx="1.92708333333e-05" ixy="0" ixz="0" iyy="2.42708333333e-05" iyz="0" izz="8.33333333333e-06"/>
    </inertial>
    <visual>
      <geometry>
        <mesh filename="package://perceptive_mpc/urdf/mabi/meshes/spring_link.dae" scale="0.001 0.001 0.001"/>
      </geometry>
    </visual>
    <collision>
      <origin rpy="-0.7068 0 0" xyz="0 0.018 0.018"/>
      <geometry>
        <box size="0.04 0.02 0.065"/>
      </geometry>
    </collision>
  </link>
  <!-- left finger -->
  <joint name="GRIPPER_left_driver_joint" type="fixed">
    <origin rpy="0 0 3.141592653589793" xyz="0 -0.0306011 0.054904"/>
    <parent link="GRIPPER_BASE"/>
    <child link="GRIPPER_left_driver"/>
    <axis xyz="1 0 0"/>
    <limit effort="176" lower="0.0" upper="0.872664444444" velocity="1.91986177778"/>
    <mimic joint="GRIPPER_JOINT" multiplier="1"/>
  </joint>
  <link name="GRIPPER_left_driver">
    <inertial>
      <mass value="0.05"/>
      <origin rpy="0 0 0" xyz="0 0.02 0"/>
      <inertia ixx="8.33333333333e-06" ixy="0" ixz="0" iyy="3.33333333333e-06" iyz="0" izz="8.33333333333e-06"/>
    </inertial>
    <visual>
      <geometry>
        <mesh filename="package://perceptive_mpc/urdf/mabi/meshes/driver.dae" scale="0.001 0.001 0.001"/>
      </geometry>
    </visual>
    <collision>
      <origin rpy="-0.1 0 0" xyz="0 0.02 0"/>
      <geometry>
        <box size="0.02 0.04 0.02"/>
      </geometry>
    </collision>
  </link>
  <joint name="GRIPPER_left_coupler_joint" type="fixed">
    <origin rpy="0 0 0" xyz="0 0.0315 -0.0041"/>
    <parent link="GRIPPER_left_driver"/>
    <child link="GRIPPER_left_coupler"/>
  </joint>
  <link name="GRIPPER_left_coupler">
    <inertial>
      <mass value="0.05"/>
      <origin rpy="-1.7 0 0" xyz="0 0.0 0.025"/>
      <inertia ixx="1.92708333333e-05" ixy="0" ixz="0" iyy="5.41666666667e-06" iyz="0" izz="2.13541666667e-05"/>
    </inertial>
    <visual>
      <geometry>
        <mesh filename="package://perceptive_mpc/urdf/mabi/meshes/coupler.dae" scale="0.001 0.001 0.001"/>
      </geometry>
    </visual>
    <collision>
      <origin rpy="-1.7 0 0" xyz="0 0.0 0.025"/>
      <geometry>
        <box size="0.03 0.065 0.02"/>
      </geometry>
    </collision>
  </link>
  <joint name="GRIPPER_left_follower_joint" type="fixed">
    <origin rpy="0 0 0" xyz="0 0.0061 0.0471"/>
    <parent link="GRIPPER_left_coupler"/>
    <child link="GRIPPER_left_follower"/>
    <axis xyz="1 0 0"/>
    <limit effort="176" lower="-2.96705911111" upper="2.96705911111" velocity="1.91986177778"/>
    <mimic joint="GRIPPER_JOINT" multiplier="-1"/>
  </joint>
  <link name="GRIPPER_left_follower">
    <inertial>
      <mass value="0.05"/>
      <origin xyz="0 -0.018 0.022"/>
      <inertia ixx="1.05375e-05" ixy="0" ixz="0" iyy="1.12666666667e-05" iyz="0" izz="2.60416666667e-06"/>
    </inertial>
    <visual>
      <geometry>
        <mesh filename="package://perceptive_mpc/urdf/mabi/meshes/follower.dae" scale="0.001 0.001 0.001"/>
      </geometry>
    </visual>
    <collision>
      <origin rpy="0 0 0" xyz="0 -0.018 0.022"/>
      <geometry>
        <box size="0.02 0.015 0.048"/>
      </geometry>
    </collision>
  </link>
  <joint name="GRIPPER_left_pad_joint" type="fixed">
    <parent link="GRIPPER_left_follower"/>
    <child link="GRIPPER_left_pad"/>
  </joint>
  <link name="GRIPPER_left_pad">
    <inertial>
      <mass value="0.01"/>
      <origin xyz="0 -0.022 0.031"/>
      <inertia ixx="1.13333333333e-06" ixy="0" ixz="0" iyy="1.41333333333e-06" iyz="0" izz="3.86666666667e-07"/>
    </inertial>
    <visual>
      <geometry>
        <mesh filename="package://perceptive_mpc/urdf/mabi/meshes/pad.dae" scale="0.001 0.001 0.001"/>
      </geometry>
    </visual>
    <collision>
      <origin rpy="0 0 0" xyz="0 -0.022 0.031"/>
      <geometry>
        <box size="0.02 0.008 0.036"/>
      </geometry>
    </collision>
  </link>
  <gazebo reference="GRIPPER_left_pad">
    <kp>1000000.0</kp>
    <kd>1.5</kd>
    <mu1>1.2</mu1>
    <mu2>1.2</mu2>
  </gazebo>
  <joint name="GRIPPER_left_spring_link_joint" type="fixed">
    <origin rpy="0 0 3.141592653589793" xyz="0 -0.012 0.0614"/>
    <parent link="GRIPPER_BASE"/>
    <child link="GRIPPER_left_spring_link"/>
    <axis xyz="1 0 0"/>
    <limit effort="176" lower="-2.96705911111" upper="2.96705911111" velocity="1.91986177778"/>
    <mimic joint="GRIPPER_JOINT" multiplier="1"/>
  </joint>
  <link name="GRIPPER_left_spring_link">
    <inertial>
      <mass value="0.05"/>
      <origin rpy="-0.7068 0 0" xyz="0 0.018 0.018"/>
      <inertia ixx="1.92708333333e-05" ixy="0" ixz="0" iyy="2.42708333333e-05" iyz="0" izz="8.33333333333e-06"/>
    </inertial>
    <visual>
      <geometry>
        <mesh filename="package://perceptive_mpc/urdf/mabi/meshes/spring_link.dae" scale="0.001 0.001 0.001"/>
      </geometry>
    </visual>
    <collision>
      <origin rpy="-0.7068 0 0" xyz="0 0.018 0.018"/>
      <geometry>
        <box size="0.04 0.02 0.065"/>
      </geometry>
    </collision>
  </link>
  <transmission name="GRIPPER_right_driver_trans">
    <type>transmission_interface/SimpleTransmission</type>
    <joint name="GRIPPER_JOINT">
      <hardwareInterface>hardware_interface/PositionJointInterface</hardwareInterface>
    </joint>
    <actuator name="GRIPPER_right_driver_motor">
      <mechanicalReduction>1</mechanicalReduction>
    </actuator>
  </transmission>
  <joint name="GRIPPER_BASE_ENDEFFECTOR_JOINT" type="fixed">
    <origin rpy="0 0 0" xyz="0 0 0.14"/>
    <parent link="GRIPPER_BASE"/>
    <child link="ENDEFFECTOR"/>
  </joint>
  <link name="ENDEFFECTOR"/>
  <!-- Base link is the center of the robot's bottom plate -->
  <link name="base_link">
    <visual>
      <origin rpy="0 0 0" xyz="0 0 0"/>
      <geometry>
        <mesh filename="package://perceptive_mpc/urdf/mabi/meshes/base_simplified.stl"/>
      </geometry>
      <material name="gray">
        <color rgba="0.4 0.4 0.4 1"/>
      </material>
    </visual>
    <collision>
      <origin rpy="0 0 0" xyz="0 0 0.299"/>
      <geometry>
        <box size="0.8 0.7 0.02"/>
      </geometry>
    </collision>
    <collision>
      <origin rpy="0 0 0" xyz="0.39 0 0.1445"/>
      <geometry>
        <box size="0.02 0.7 0.289"/>
      </geometry>
    </collision>
    <collision>
      <origin rpy="0 0 0" xyz="-0.39 0 0.1445"/>
      <geometry>
        <box size="0.02 0.7 0.289"/>
      </geometry>
    </collision>
    <collision>
      <origin rpy="0 0 0" xyz="0 0.34 0.1445"/>
      <geometry>
        <box size="0.76 0.02 0.289"/>
      </geometry>
    </collision>
    <collision>
      <origin rpy="0 0 0" xyz="0 -0.34 0.1445"/>
      <geometry>
        <box size="0.76 0.02 0.289"/>
      </geometry>
    </collision>
    <self_filter>
      <origin rpy="0 0 0" xyz="0 0 0.1545"/>
      <geometry>
        <box size="0.8 0.7 0.309"/>
      </geometry>
    </self_filter>
  </link>
  <!-- Base footprint is on the ground plate of the robot -->
  <link name="base_footprint"/>
  <joint name="base_footprint_joint" type="fixed">
    <origin rpy="0 0 0" xyz="0 0 -0.05"/>
    <parent link="base_link"/>
    <child link="base_footprint"/>
  </joint>
  <!-- Interial link stores the robot's inertial information -->
  <link name="base_link_inertia">
    <inertial>
      <mass value="60"/>
      <!-- Update inertias -->
      <origin xyz="0.0 0.0 0.0"/>
      <inertia ixx="2.927405" ixy="0.0" ixz="0.0" iyy="3.677405" iyz="0.0" izz="5.6274"/>
    </inertial>
  </link>
  <joint name="inertial_joint" type="fixed">
    <origin rpy="0 0 0" xyz="0 0 0.1545"/>
    <parent link="base_link"/>
    <child link="base_link_inertia"/>
  </joint>
  <link name="L_WHEEL">
    <inertial>
      <mass value="10.9"/>
      <origin xyz="0 0 0"/>
      <inertia ixx="0.0645825" ixy="0" ixz="0" iyy="0.122625" iyz="0" izz="0.0645825"/>
    </inertial>
    <visual>
      <origin rpy="0 0 0" xyz="0 0 0"/>
      <geometry>
        <mesh filename="package://perceptive_mpc/urdf/mabi/meshes/wheel_simplified.stl"/>
      </geometry>
      <material name="gray">
        <color rgba="0.4 0.4 0.4 1"/>
      </material>
    </visual>
    <collision>
      <origin rpy="1.5707963268 0 0" xyz="0 0 0"/>
      <geometry>
        <cylinder length="0.06" radius="0.15"/>
      </geometry>
    </collision>
  </link>
  <gazebo reference="L_WHEEL">
    <mu1 value="1.0"/>
    <mu2 value="1.0"/>
    <kp value="10000000.0"/>
    <kd value="1.0"/>
    <fdir1 value="1 0 0"/>
  </gazebo>
  <joint name="J_L_WHEEL" type="fixed">
    <parent link="base_link"/>
    <child link="L_WHEEL"/>
    <origin rpy="0 0 0" xyz="0.0 0.29 0.1"/>
    <axis rpy="0 0 0" xyz="0 1 0"/>
    <limit effort="50" velocity="100"/>
  </joint>
  <transmission name="L_WHEEL_TRANS" type="SimpleTransmission">
    <type>transmission_interface/SimpleTransmission</type>
    <actuator name="L_WHEEL_MOTOR">
      <mechanicalReduction>1</mechanicalReduction>
    </actuator>
    <joint name="J_L_WHEEL">
      <hardwareInterface>hardware_interface/VelocityJointInterface</hardwareInterface>
    </joint>
  </transmission>
  <link name="R_WHEEL">
    <inertial>
      <mass value="10.9"/>
      <origin xyz="0 0 0"/>
      <inertia ixx="0.0645825" ixy="0" ixz="0" iyy="0.122625" iyz="0" izz="0.0645825"/>
    </inertial>
    <visual>
      <origin rpy="0 0 0" xyz="0 0 0"/>
      <geometry>
        <mesh filename="package://perceptive_mpc/urdf/mabi/meshes/wheel_simplified.stl"/>
      </geometry>
      <material name="gray">
        <color rgba="0.4 0.4 0.4 1"/>
      </material>
    </visual>
    <collision>
      <origin rpy="1.5707963268 0 0" xyz="0 0 0"/>
      <geometry>
        <cylinder length="0.06" radius="0.15"/>
      </geometry>
    </collision>
  </link>
  <gazebo reference="R_WHEEL">
    <mu1 value="1.0"/>
    <mu2 value="1.0"/>
    <kp value="10000000.0"/>
    <kd value="1.0"/>
    <fdir1 value="1 0 0"/>
  </gazebo>
  <joint name="J_R_WHEEL" type="fixed">
    <parent link="base_link"/>
    <child link="R_WHEEL"/>
    <origin rpy="0 0 0" xyz="0.0 -0.29 0.1"/>
    <axis rpy="0 0 0" xyz="0 1 0"/>
    <limit effort="50" velocity="100"/>
  </joint>
  <transmission name="R_WHEEL_TRANS" type="SimpleTransmission">
    <type>transmission_interface/SimpleTransmission</type>
    <actuator name="R_WHEEL_MOTOR">
      <mechanicalReduction>1</mechanicalReduction>
    </actuator>
    <joint name="J_R_WHEEL">
      <hardwareInterface>hardware_interface/VelocityJointInterface</hardwareInterface>
    </joint>
  </transmission>
  <!-- Caster Wheels (collision only) -->
  <link name="cw_fl_link">
    <inertial>
      <mass value="3.0"/>
      <origin xyz="0 0 0"/>
      <inertia ixx="0.002275" ixy="0" ixz="0" iyy="0.00375" iyz="0" izz="0.002275"/>
    </inertial>
    <collision>
      <origin rpy="1.5707963268 0 0" xyz="0 0 0"/>
      <geometry>
        <cylinder length="0.04" radius="0.05"/>
      </geometry>
    </collision>
  </link>
  <gazebo reference="cw_fl_link">
    <mu1 value="0.0"/>
    <mu2 value="0.0"/>
    <kp value="10000000.0"/>
    <kd value="1.0"/>
    <fdir1 value="1 0 0"/>
  </gazebo>
  <link name="cw_fr_link">
    <inertial>
      <mass value="3.0"/>
      <origin xyz="0 0 0"/>
      <inertia ixx="0.002275" ixy="0" ixz="0" iyy="0.00375" iyz="0" izz="0.002275"/>
    </inertial>
    <collision>
      <origin rpy="1.5707963268 0 0" xyz="0 0 0"/>
      <geometry>
        <cylinder length="0.04" radius="0.05"/>
      </geometry>
    </collision>
  </link>
  <gazebo reference="cw_fr_link">
    <mu1 value="0.0"/>
    <mu2 value="0.0"/>
    <kp value="10000000.0"/>
    <kd value="1.0"/>
    <fdir1 value="1 0 0"/>
  </gazebo>
  <link name="cw_hl_link">
    <inertial>
      <mass value="3.0"/>
      <origin xyz="0 0 0"/>
      <inertia ixx="0.002275" ixy="0" ixz="0" iyy="0.00375" iyz="0" izz="0.002275"/>
    </inertial>
    <collision>
      <origin rpy="1.5707963268 0 0" xyz="0 0 0"/>
      <geometry>
        <cylinder length="0.04" radius="0.05"/>
      </geometry>
    </collision>
  </link>
  <gazebo reference="cw_hl_link">
    <mu1 value="0.0"/>
    <mu2 value="0.0"/>
    <kp value="10000000.0"/>
    <kd value="1.0"/>
    <fdir1 value="1 0 0"/>
  </gazebo>
  <link name="cw_hr_link">
    <inertial>
      <mass value="3.0"/>
      <origin xyz="0 0 0"/>
      <inertia ixx="0.002275" ixy="0" ixz="0" iyy="0.00375" iyz="0" izz="0.002275"/>
    </inertial>
    <collision>
      <origin rpy="1.5707963268 0 0" xyz="0 0 0"/>
      <geometry>
        <cylinder length="0.04" radius="0.05"/>
      </geometry>
    </collision>
  </link>
  <gazebo reference="cw_hr_link">
    <mu1 value="0.0"/>
    <mu2 value="0.0"/>
    <kp value="10000000.0"/>
    <kd value="1.0"/>
    <fdir1 value="1 0 0"/>
  </gazebo>
  <joint name="cw_fl" type="fixed">
    <parent link="base_link"/>
    <child link="cw_fl_link"/>
    <origin rpy="0 0 0" xyz="0.25 0.185 0.005"/>
    <axis rpy="0 0 0" xyz="0 1 0"/>
    <dynamics damping="0.1" friction="0.2"/>
    <limit effort="50" velocity="100"/>
  </joint>
  <joint name="cw_fr" type="fixed">
    <parent link="base_link"/>
    <child link="cw_fr_link"/>
    <origin rpy="0 0 0" xyz="0.25 -0.185 0.005"/>
    <axis rpy="0 0 0" xyz="0 1 0"/>
    <dynamics damping="0.1" friction="0.2"/>
    <limit effort="50" velocity="100"/>
  </joint>
  <joint name="cw_hl" type="fixed">
    <parent link="base_link"/>
    <child link="cw_hl_link"/>
    <origin rpy="0 0 0" xyz="-0.25 0.185 0.005"/>
    <axis rpy="0 0 0" xyz="0 1 0"/>
    <dynamics damping="0.1" friction="0.2"/>
    <limit effort="50" velocity="100"/>
  </joint>
  <joint name="cw_hr" type="fixed">
    <parent link="base_link"/>
    <child link="cw_hr_link"/>
    <origin rpy="0 0 0" xyz="-0.25 -0.185 0.005"/>
    <axis rpy="0 0 0" xyz="0 1 0"/>
    <dynamics damping="0.1" friction="0.2"/>
    <limit effort="50" velocity="100"/>
  </joint>
  <link name="arm_base">
    <inertial>
      <mass value="0.0001"/>
      <origin xyz="0 0 0"/>
      <inertia ixx="0.0001" ixy="0" ixz="0" iyy="0.0001" iyz="0" izz="0.0001"/>
    </inertial>
  </link>
  <joint name="base_to_arm_base" type="fixed">
    <child link="arm_base"/>
    <parent link="base_link"/>
    <origin rpy="0 0 1.57079632679" xyz="0 0 0.309"/>
  </joint>
  <!-- Attaching additional sensors and frames to the base -->
  <!-- IMU Link -->
  <link name="imu_link"/>
  <joint name="imu_joint" type="fixed">
    <origin rpy="3.14159265359 0 3.14159265359" xyz="0.20 0 0.1351"/>
    <parent link="base_link"/>
    <child link="imu_link"/>
  </joint>
  <link name="camera_mount"/>
  <joint name="base_to_camera_mount" type="fixed">
    <child link="camera_mount"/>
    <parent link="base_link"/>
    <origin rpy="3.14159265359 -1.5707963268 0" xyz="-0.38745 -0.00911 0.32995"/>
  </joint>
  <link name="camera_vr_orientation"/>
  <joint name="camera_ros_to_vr_convention" type="fixed">
    <child link="camera_vr_orientation"/>
    <parent link="camera_mount"/>
    <origin rpy="1.5707963268 0 -1.5707963268" xyz="0 0 0"/>
  </joint>
  <link name="realsense_odom_input_frame"/>
  <joint name="base_to_realsense_odom_input_frame" type="fixed">
    <child link="realsense_odom_input_frame"/>
    <parent link="base_link"/>
    <origin rpy="0 0 0" xyz="0 0 0.1"/>
  </joint>
</robot>
